---
layout: post
title: "Handling failures and retries with Asyncio"
description: " "
date: 2023-09-15
tags: [asyncio, failurehandling]
comments: true
share: true
---

In asynchronous programming with `Asyncio`, it is essential to handle failures and retries properly to build robust and error-resistant applications. In this blog post, we will explore different strategies and techniques to handle failures and retries effectively using `Asyncio`.

## Understanding Failures

Failures can occur due to various reasons such as network issues, resource unavailability, or external service errors. It is essential to handle these failures gracefully to prevent cascading failures and ensure the smooth execution of your `Asyncio` code.

## Retrying Strategies

### Exponential Backoff

One common retry strategy is the exponential backoff. In this strategy, we gradually increase the delay between successive retries, giving the system more time to recover.

```python
import asyncio

async def fetch_data(url):
    for attempt in range(3):
        try:
            # code to fetch data from the URL
            data = await some_async_function(url)
            return data
        except Exception as e:
            print(f"Error: {e}")
            await asyncio.sleep(2 ** attempt)

    raise Exception("Failed after multiple attempts")

loop = asyncio.get_event_loop()
loop.run_until_complete(fetch_data("https://example.com"))
```

In the above example, we attempt to fetch data from a URL using an asynchronous function. If an exception occurs, we print the error and wait for an exponentially increasing amount of time before the next attempt. This strategy gives the system more time to recover from transient failures.

### Fixed Delay

Another retry strategy is the fixed delay, where we wait for a fixed amount of time between each retry.

```python
import asyncio

async def fetch_data(url):
    for attempt in range(3):
        try:
            # code to fetch data from the URL
            data = await some_async_function(url)
            return data
        except Exception as e:
            print(f"Error: {e}")
            await asyncio.sleep(5)

    raise Exception("Failed after multiple attempts")

loop = asyncio.get_event_loop()
loop.run_until_complete(fetch_data("https://example.com"))
```

In this example, we wait for a fixed delay of 5 seconds between each retry. While this strategy is simpler than exponential backoff, it may not be as effective in handling high load scenarios or when there are multiple concurrent retries.

### Error Limit

In some cases, it may be beneficial to limit the number of retries based on the type of error encountered. For example, if the error is a connection timeout, it might make sense to retry multiple times. However, if the error is a permanent failure, such as a 404 response, it may not be worth retrying.

```python
import asyncio

async def fetch_data(url):
    for attempt in range(3):
        try:
            # code to fetch data from the URL
            data = await some_async_function(url)
            return data
        except ConnectionTimeoutError as e:
            print(f"Connection timeout: {e}")
            await asyncio.sleep(5)
        except PermanentFailureError as e:
            print(f"Permanent failure: {e}")
            break

    raise Exception("Failed after multiple attempts")

loop = asyncio.get_event_loop()
loop.run_until_complete(fetch_data("https://example.com"))
```

In this example, we catch specific types of exceptions and handle them differently. For connection timeouts, we retry after a fixed delay, whereas for permanent failures, we break out of the retry loop.

## Conclusion

Handling failures and retries is crucial when building robust asynchronous applications with `Asyncio`. By implementing effective retry strategies, such as exponential backoff or fixed delay, and distinguishing between different types of failures, you can ensure that your code is resilient to failures and provides a smoother user experience.

#asyncio #failurehandling