---
layout: post
title: "Exception handling in Asyncio"
description: " "
date: 2023-09-15
tags: [asyncio, exceptionhandling]
comments: true
share: true
---

In asynchronous programming with asyncio, handling exceptions is crucial to ensure the stability and reliability of your code. Asyncio provides several mechanisms to catch and handle exceptions raised within async functions and coroutines. In this blog post, we will explore the different approaches to exception handling in asyncio and discuss when to use each one.

## 1. try-except blocks

The most basic way to handle exceptions in asyncio is by using standard try-except blocks. You can wrap your async blocks of code with a try statement and catch specific exceptions using the except clause.

```python
import asyncio

async def my_async_function():
    try:
        # Asynchronous code goes here
        await asyncio.sleep(1)
        
    except Exception as e:
        # Handle exception here
        print(f"Exception: {e}")
```

Using try-except blocks allows you to catch and handle specific exceptions within your async functions. However, it's important to note that using try-except blocks inside every individual async function can quickly become repetitive and clutter your code.

## 2. asyncio.gather

Another approach to exception handling in asyncio is by using the `asyncio.gather` function. `asyncio.gather` allows you to run multiple async functions concurrently and handles exceptions raised by any of the functions.

```python
import asyncio

async def task1():
    # Asynchronous code for task 1 goes here

async def task2():
    # Asynchronous code for task 2 goes here

async def main():
    try:
        tasks = [task1(), task2()]
        await asyncio.gather(*tasks)
    
    except Exception as e:
        # Handle exception here
        print(f"Exception: {e}")
```

By wrapping your async functions with `asyncio.gather`, any exception raised within those functions will be caught and propagated to the main exception handler. This approach simplifies exception handling when dealing with multiple async functions.

## 3. External Error Handler

A more advanced approach to exception handling in asyncio is to use an external error handler. You can set a custom error handler using `asyncio.loop.set_exception_handler`, which allows you to define how the event loop should handle uncaught exceptions.

```python
import asyncio

def custom_exception_handler(loop, context):
    # Handle exception here
    exception = context.get('exception')
    print(f"Uncaught exception: {exception}")

async def my_async_function():
    # Asynchronous code goes here

# Set the custom exception handler
loop = asyncio.get_event_loop()
loop.set_exception_handler(custom_exception_handler)
```

By defining a custom exception handler, you can centralize your exception handling logic and have more control over how exceptions are logged or handled within your async code.

## Conclusion

Exception handling is an essential aspect of writing robust and error-resilient asynchronous code in asyncio. Whether you choose to use try-except blocks, asyncio.gather, or a custom error handler, make sure to handle exceptions appropriately to prevent unexpected crashes and ensure the smooth running of your async code.

#python #asyncio #exceptionhandling