---
layout: post
title: "Exception handling in Python functions"
description: " "
date: 2023-09-29
tags: [techblog]
comments: true
share: true
---

Exception handling is a crucial aspect of writing robust and reliable code. It enables us to handle potential errors or exceptional situations in our code gracefully, preventing the program from crashing unexpectedly. In this blog post, we will explore how to implement exception handling in Python functions effectively.

## Why Exception Handling?

When we execute a program, unexpected errors may occur. These errors could be due to various reasons, such as invalid input, network failures, or file access issues. Without proper exception handling, these errors can cause our program to terminate abruptly, leading to a poor user experience or even data loss.

Exception handling allows us to anticipate and handle these potential errors in a controlled manner. By handling exceptions, we can prevent our program from crashing and provide meaningful error messages to users. This helps in troubleshooting, making our code more reliable and robust.

## Handling Exceptions in Python Functions

To handle exceptions in Python functions, we use the `try-except` block. The `try` block contains the code that potentially raises an exception, while the `except` block catches the exception and handles it appropriately. The general syntax is as follows:

```python
try:
    # Code that may raise an exception
except ExceptionType:
    # Code to handle the exception
```

Let's consider an example where we have a function that divides two numbers:

```python
def divide_numbers(a, b):
    try:
        result = a / b
        return result
    except ZeroDivisionError:
        print("Error: Division by zero!")
```

In the above code, we attempt to divide `a` by `b` inside the `try` block. If a `ZeroDivisionError` occurs, the control is transferred to the `except` block, where we print an appropriate error message.

## Handling Multiple Exceptions

We can handle multiple exceptions using multiple `except` blocks or a single `except` block that catches multiple exceptions. Here's an example:

```python
def calculate():
    try:
        # Some code that may raise exceptions
    except ValueError:
        # Code to handle a ValueError
    except FileNotFoundError:
        # Code to handle a FileNotFoundError
```

In the above code, we have separate `except` blocks to handle `ValueError` and `FileNotFoundError` exceptions. We can also combine these exceptions into a single `except` block:

```python
def calculate():
    try:
        # Some code that may raise exceptions
    except (ValueError, FileNotFoundError) as e:
        # Code to handle the exception
        print(f"An error occurred: {e}")
```

## Finally Block

In addition to the `try` and `except` blocks, we also have an optional `finally` block. The code inside the `finally` block is executed regardless of whether an exception is raised or not. It is commonly used to perform cleanup operations or release resources.

```python
try:
    # Code that may raise an exception
except ExceptionType:
    # Code to handle the exception
finally:
    # Code that always executes, regardless of exceptions
```

## Conclusion

Exception handling is a powerful mechanism in Python for handling errors and exceptional situations in our code. By using the `try-except` block, we can gracefully handle exceptions, preventing our program from crashing unexpectedly. It is important to anticipate potential exceptions in our code and handle them properly to improve the reliability and robustness of our software.

#techblog #python