---
layout: post
title: "Controlling the execution flow with generators and the throw() method"
description: " "
date: 2023-09-27
tags: [JavaScript, Generators]
comments: true
share: true
---

To define a generator function in JavaScript, we use the `function*` syntax. Inside the generator function, we can use the `yield` keyword to pause the execution and return a value. Let's see a simple example:

```javascript
function* numberGenerator() {
    yield 1;
    yield 2;
    yield 3;
}

const generator = numberGenerator();
console.log(generator.next()); // { value: 1, done: false }
console.log(generator.next()); // { value: 2, done: false }
console.log(generator.next()); // { value: 3, done: false }
console.log(generator.next()); // { value: undefined, done: true }
```

In the example above, we define a generator function `numberGenerator()` that yields three numbers: 1, 2, and 3. We create an instance of the generator using `numberGenerator()`, and then call the `next()` method to resume the execution. The `next()` method returns an object with the `value` and `done` properties. If the generator function has more values to yield, `done` will be `false`. Once the generator has finished executing, `done` will be `true`.

Now, let's see how we can use the `throw()` method to handle errors inside a generator:

```javascript
function* errorHandler() {
    try {
        yield 1;
        yield 2;
        throw new Error("Something went wrong");
        yield 3;
    } catch (error) {
        yield "Error caught: " + error.message;
    }
}

const generator = errorHandler();
console.log(generator.next()); // { value: 1, done: false }
console.log(generator.next()); // { value: 2, done: false }
console.log(generator.throw(new Error("Test error"))); // { value: 'Error caught: Test error', done: false }
console.log(generator.next()); // { value: undefined, done: true }
```

In the above example, we have a generator function `errorHandler()` that throws an error after yielding the number 2. We use a try-catch block to catch the error and yield a custom error message. To trigger the error, we use the `throw()` method on the generator instance. The `throw()` method throws an error inside the generator, which is then caught by the try-catch block.

Generators are a versatile tool that can be used to control the execution flow and handle errors in a more structured way. By understanding how to use `yield`, `next()`, and `throw()`, you can write more expressive and maintainable asynchronous code.

#JavaScript #Generators #ErrorHandling