---
layout: post
title: "Handling exceptions in Python generators"
description: " "
date: 2023-09-27
tags: [Generators]
comments: true
share: true
---

Python generators are a powerful tool for controlling the flow of data in a concise and memory-efficient manner. However, when it comes to error handling, working with generators can be a bit tricky.

Generators allow you to pause and resume execution at any point, which makes exception handling more challenging compared to regular functions. When an exception occurs inside a generator, it can't be caught using a traditional `try-except` block.

To handle exceptions in Python generators, you can use the `try-except` block inside the generator function. Here's an example:

```python
def my_generator():
    yield 1
    try:
        yield 2
        yield 3
        raise ValueError("Something went wrong!")
    except ValueError as e:
        yield f"Error occurred: {str(e)}"
    yield 4

gen = my_generator()

for item in gen:
    print(item)
```

In this example, we define a generator function `my_generator()` that yields a sequence of numbers. Inside the generator, we raise a `ValueError` exception to demonstrate the error handling mechanism.

When the exception is raised, it is caught inside the generator using the `try-except` block. The generator then yields a string indicating that an error occurred. Finally, the generator resumes execution and yields the remaining items.

Executing the code will produce the following output:

```
1
2
3
Error occurred: Something went wrong!
4
```

By catching the exception inside the generator, we can handle the error gracefully and continue the execution of the generator.

Another way to handle exceptions in generators is by using the `throw()` method. The `throw()` method allows you to raise an exception inside the generator from outside. Here's an example:

```python
def my_generator():
    yield 1
    yield 2
    yield 3

gen = my_generator()

try:
    for item in gen:
        print(item)
        if item == 2:
            gen.throw(ValueError("Something went wrong!"))
except ValueError as e:
    print(f"Error occurred: {str(e)}")
```

In this example, we iterate over the generator and check if the current item is `2`. If it is, we use the `throw()` method to raise a `ValueError` exception. Outside the generator, we catch the exception and print an error message.

The output will be:

```
1
2
Error occurred: Something went wrong!
```

Using the `try-except` block inside the generator or the `throw()` method from outside, you can handle exceptions effectively in Python generators. These techniques provide flexibility and control when working with generators and exceptional conditions.

#Python #Generators